Workbook

Sheet الاصناف
A1: COMP | B1: GOID | C1: BARCODE | D1: MAIN GOID | E1: Item_name | F1: Item_name2 | G1: Sale1 | H1: Sale2 | I1: Sale3 | J1: Sale4 | K1: Sale5 | L1: VAT | M1: Branch | N1: Qty | O1: HQty | P1: Cost | Q1: TotalCost | R1: SET | S1: Category | T1: Unit | U1: Brand | V1: Origin | W1: Supplier | X1: Size | Y1: Color | Z1: Family | AA1: Group | AB1: HIGHT | AC1: WEIGHT | AD1: THICKNESS | AE1: UMLASALEPRICE | AF1: Sale1TTC | AG1: Sale2TTC | AH1: Sale3TTC | AI1: Sale4TTC | AJ1: Sale5TTC | AK1: Set_Name | AL1: Category_Name | AM1: Unit_Name | AN1: Brand_Name | AO1: Origin_Name | AP1: Supplier_Name | AQ1: DSize_Name | AR1: Color_Name | AS1: Family_Name | AT1: Group_Name
A2: NOUR26 | B2: JNZR-T | C2: JNZR-T | E2: LEO 3HP 380V 2 TURB | M2: 1 | N2: -8 | O2: 0 | P2: 12.5 | Q2: -100 | W2: 400017 | AE2: 0 | AP2: غنوم
A3: NOUR26 | B3: GKK | C3: GKK | E3: LEO / COMET FLOW SWITCH FS01 | I3: 1 | M3: 1 | N3: -28 | O3: 0 | P3: 0.65 | Q3: -18.2 | R3: 0 | S3: 0 | T3: PCS | U3: 0 | V3: 0 | W3: 400119 | AE3: 0 | AH3: 1 | AP3: الشيخ احمد عز الدين
A4: NOUR26 | B4: JOINT | C4: JOINT | E4: LEO 15-90A/160 طلمبة اوتوماتيك | M4: 1 | N4: 2 | O4: 0 | P4: 7 | Q4: 14 | R4: 1 | S4: 0 | T4: 0 | U4: 0 | V4: 0 | W4: 400017 | X4: GALON | Y4: WHITE | AE4: 0 | AK4: SET 1 | AP4: غنوم
A5: NOUR26 | B5: JAWZE | C5: JAWZE | E5: LEO 2 HP 220V 2 TURBINE /66MTS | M5: 1 | N5: 592 | O5: 0 | P5: 2.25 | Q5: 1332 | R5: 0 | S5: 0 | T5: 0 | U5: 0 | V5: 0 | W5: 400158 | X5: GALON | Y5: WHITE | AE5: 0 | AP5: علي بازون
A6: NOUR26 | B6: JELEH | C6: JELEH | E6: LEO 24 LT بالون ضغط | M6: 1 | N6: -8 | O6: 0 | P6: 1.66 | Q6: -13.32 | R6: 0 | S6: 0 | T6: PCS | W6: 400017 | AE6: 0 | AP6: غنوم
A7: NOUR26 | B7: HT | C7: HT | E7: LEO 2AC300H 4HP 2 TURB 380V | M7: 1 | N7: -1 | O7: 0 | P7: 58.28 | Q7: -58.28 | R7: 0 | S7: 0 | T7: 0 | W7: 400010 | AE7: 0 | AP7: ميوركس
A8: NOUR26 | B8: HBL | C8: HBL | E8: LEO 2ACm150 2HP 220V موتير ليو توربين | G8: 175 | M8: 1 | N8: -38.35 | O8: 0 | P8: 1 | Q8: -38.35 | R8: 0 | S8: 0 | T8: 0 | U8: 0 | V8: 0 | W8: 400017 | X8: GALON | Y8: WHITE | AE8: 0 | AP8: غنوم
A9: NOUR26 | B9: HBLGHSL | C9: HBLGHSL | E9: LEO 2ACM150 طقم فراشات | M9: 1 | N9: 1056.5 | O9: 0 | P9: 1.4 | Q9: 1479.1 | R9: 0 | S9: 0 | T9: KILO | U9: 0 | V9: 0 | W9: 400158 | X9: GALON | Y9: WHITE | AE9: 0 | AP9: علي بازون
E10: LEO 3HP 220V 2TURB
A11: NOUR26 | B11: HAGAR10 | C11: HAGAR10 | E11: LEO 3HP 2XCM25/160A 220V 2 TURB | M11: 1 | N11: -4033 | O11: 0 | P11: 5.94 | Q11: -23958.44 | R11: 0 | S11: 0 | T11: PCS | W11: 400150 | AE11: 0 | AP11: حسن الحريري ترابة ورمل لبناني
A12: NOUR26 | B12: HAGAR12 | C12: HAGAR12 | E12: LEO 4 ACM/60 طلمبة ماء صامته | G12: 100 | M12: 1 | N12: -1177 | O12: 0 | P12: 1.58 | Q12: -1864.55 | R12: 0 | S12: 0 | T12: PCS | W12: 400150 | AE12: 0 | AP12: حسن الحريري ترابة ورمل لبناني
A13: NOUR26 | B13: HAGAR15 | C13: HAGAR15 | E13: LEO 4 ACM/75 طلمبة ماء صامتة | G13: 125 | M13: 1 | N13: -811 | O13: 0 | P13: 5.45 | Q13: -4416.3 | R13: 0 | S13: 0 | T13: PCS | W13: 400150 | AE13: 0 | AP13: حسن الحريري ترابة ورمل لبناني
A14: NOUR26 | B14: HAGAR20 | C14: HAGAR20 | E14: LEO 4XCM 120C 1HP موتير ماء صامته ستانلس | M14: 1 | N14: -23 | O14: 0 | P14: 1.06 | Q14: -24.29 | R14: 0 | S14: 0 | T14: PCS | W14: 400089 | AE14: 0 | AP14: حسن الحريري - ترابة ورمل $
A15: NOUR26 | B15: HAGAR6 | C15: HAGAR6 | E15: LEO 65WQ25-22-3 4HP موتير فرامة | M15: 1 | N15: -548 | O15: 0 | P15: 2.64 | Q15: -1446.86 | R15: 0 | S15: 0 | T15: PCS | W15: 400150 | AE15: 0 | AP15: حسن الحريري ترابة ورمل لبناني
A16: NOUR26 | B16: HAGAR8 | C16: HAGAR8 | E16: LEO AJM 60H JET 0.75 HP موتير سارق | M16: 1 | N16: -56 | O16: 0 | P16: 0.3 | Q16: -16.8 | R16: 0 | S16: 0 | T16: PCS | W16: 410004 | AE16: 0 | AP16: السادة محلات واصف سنو المحترمين
A17: NOUR26 | B17: HAGAR | C17: HAGAR | E17: LEO APM150 2 طلمبة ماء عادي | M17: 1 | N17: 38 | O17: 0 | P17: 1.75 | Q17: 66.5 | R17: 0 | S17: 0 | T17: PCS | U17: 0 | V17: 0 | W17: 400017 | X17: GALON | Y17: WHITE | AE17: 0 | AP17: غنوم
A18: NOUR26 | B18: HAG-FOF | C18: HAG-FOF | E18: LEO EASY PTRESS/N | M18: 1 | N18: 5 | O18: 0 | P18: 10 | Q18: 50 | W18: 400030 | AE18: 0 | AP18: علي قبيسي
A19: NOUR26 | B19: HD | C19: HD | E19: LEO EMHM 4-7 1.75HP طلمبة صامته فراش ستانلس | M19: 1 | N19: -1 | O19: 0 | AE19: 0
E20: LEO EMHM 8-4 3HP طلمبة صامته فراش ستانلس
A21: NOUR26 | B21: HRQ | C21: HRQ | E21: LEO EMHM4-6 1.5 HP موتير صامت فراش | M21: 1 | N21: 49 | O21: 0 | P21: 2.5 | Q21: 122.5 | R21: 0 | S21: 0 | T21: PCS | U21: 0 | V21: 0 | W21: 400154 | X21: GALON | Y21: WHITE | AE21: 0 | AP21: عمر اسومه كهرباء
A22: NOUR26 | B22: HARK-C | C22: HARK-C | E22: LEO EVPM 2-9 2HP طلمبة ماء عامودية | M22: 1 | N22: 5 | O22: 0 | P22: 7 | Q22: 35 | R22: 0 | S22: 0 | T22: PCS | W22: 400030 | AE22: 0 | AP22: علي قبيسي
A23: NOUR26 | B23: HZAM | C23: HZAM | E23: LEO LVR 4-16 4 HP 380 V طلمبة عامودية | M23: 1 | N23: 2 | O23: 0 | P23: 8 | Q23: 16 | W23: 400017 | AE23: 0 | AP23: غنوم
A24: NOUR26 | B24: HFF | C24: HFF | E24: LEO LVR 4-22 5.5HP 380 V طلمبة عامودية | M24: 1 | N24: 157 | O24: 0 | P24: 1 | Q24: 157 | R24: 0 | S24: 0 | T24: PCS | U24: 0 | V24: 0 | W24: 400154 | X24: GALON | Y24: WHITE | AE24: 0 | AP24: عمر اسومه كهرباء
A25: NOUR26 | B25: LCICOLNSABI15*7.5 | C25: LCICOLNSABI15*7.5 | E25: LEO PQ50E طلمبة ماء اتوماتيك مع غطاء | G25: 80 | I25: 11 | M25: 1 | N25: 2 | O25: 0 | P25: 6.12 | Q25: 12.23 | R25: LECICO | S25: 0 | T25: PCS | U25: 0 | V25: 0 | W25: 400010 | AE25: 0 | AH25: 11 | AP25: ميوركس
A26: NOUR26 | B26: PROT | C26: PROT | E26: LEO PRESS CONTROL | G26: 25 | M26: 1 | N26: 9 | O26: 0 | P26: 4.5 | Q26: 40.5 | R26: 0 | S26: 0 | T26: 0 | U26: 0 | V26: 0 | W26: 400154 | AE26: 0 | AP26: عمر اسومه كهرباء
A27: NOUR26 | B27: HB | C27: HB | E27: LEO XKP2204 380V موتير مسبح | M27: 1 | N27: 320 | O27: 0 | P27: 2.25 | Q27: 720 | R27: 0 | S27: 0 | T27: PCS | U27: 0 | V27: 0 | W27: 410120 | AE27: 0 | AP27: السادة محلات الحنون المحترمين
A28: NOUR26 | B28: MIXHA1/2 TAK | C28: MIXHA1/2 TAK | E28: LEO بالون ضغط 100 ليتر | M28: 1 | N28: -11 | O28: 0 | R28: MIXER | S28: 0 | T28: SET | U28: 0 | V28: 0 | W28: 400002 | X28: GALON | Y28: WHITE | AE28: 0 | AP28: وسام عيتاني
E29: LEO بالون ضغط 50 ليتر
A30: NOUR26 | B30: HANAF-T-C | C30: HANAF-T-C | E30: LEO موتير 0.5 حصان صامت ليو 3ACM45 | G30: 85 | M30: 1 | N30: 117 | O30: 0 | P30: 3.5 | Q30: 409.5 | R30: 0 | S30: 0 | T30: PCS | U30: 0 | V30: 0 | W30: 400186 | X30: GALON | Y30: WHITE | AE30: 0 | AP30: حسن قرمش
A31: NOUR26 | B31: HOQN | C31: HOQN | E31: LEO موتير 0.5 حصان ليو ACM37 TURBINE | G31: 75 | M31: 1 | N31: 2 | O31: 0 | P31: 7.5 | Q31: 15 | R31: 0 | S31: 0 | T31: 0 | U31: 0 | V31: 0 | W31: 400121 | AE31: 0 | AP31: عمر كردلي
A32: NOUR26 | B32: GHSHNF | C32: GHSHNF | E32: LEO موتير 0.5 حصان ليو AJM 30سارق | M32: 1 | N32: -98 | O32: 0 | P32: 1.45 | Q32: -142.1 | R32: 0 | S32: 0 | T32: PCS | U32: 0 | V32: 0 | W32: 400033 | AE32: 0 | AP32: ربيع البسط
E33: LEO موتير 0.5 حصان ليو APM37 | G33: 35
E34: LEO موتير 0.75 حصان صامت ليو ACM60
E35: LEO موتير 0.75 حصان ليو APM 60 | G35: 55
E36: LEO موتير 1 حصان صامت ليو | G36: 120
A37: NOUR26 | B37: HANAFK | C37: HANAFK | E37: LEO موتير 1 حصان ليو ACM75 TURBINE | M37: 1 | N37: 17 | O37: 0 | P37: 23.71 | Q37: 403.07 | R37: 0 | S37: 0 | T37: PCS | W37: 400027 | AE37: 0 | AP37: عازار
A38: NOUR26 | B38: TREM-H | C38: TREM-H | E38: LEO موتير 1 حصان ليو AJM 75 طلمبة ماء سارق | M38: 1 | N38: 28 | O38: 0 | P38: 28.38 | Q38: 794.54 | W38: 400184 | AE38: 0 | AP38: AZAR BROTHER SAL
A39: NOUR26 | B39: HL | C39: HL | E39: LEO موتير 1 حصان ليو APM 75 طلمبة ماء | M39: 1 | N39: 511 | O39: 0 | P39: 5 | Q39: 2555 | R39: 0 | S39: 0 | T39: PCS | U39: 0 | V39: 0 | W39: 400130 | AE39: 0 | AP39: فوزي عيتاني
E40: LEO موتير 1 حصان ليو APM 90 طلمبة ماء | G40: 95
...

Sheet النتائج
A1: قسطل
A2: 63
A7: {=_xlfn.LET(_xlpm.words, _xlfn._xlws.FILTER(A1:A6, A1:A6<>""), _xlfn._xlws.FILTER((الاصناف!E:E&"|"&الاصناف!G:G), _xlfn.BYROW(الاصناف!E:E, _xlfn.LAMBDA(_xlpm.name, AND(ISNUMBER(SEARCH(_xlpm.words, _xlpm.name))))), "لا نتائج"))} -> قسطل المنيوم تلحيم 63 ملم اخضر تركي| | B7: =IF(A7="","",HYPERLINK("#الاصناف!E"&MATCH(LEFT(A7,FIND("|",A7)-1),الاصناف!E:E,0),"✏️ " & LEFT(A7,FIND("|",A7)-1))) -> ✏️ قسطل المنيوم تلحيم 63 ملم اخضر تركي | C7: =IF(A7="","",HYPERLINK("#الاصناف!G"&MATCH(LEFT(A7,FIND("|",A7)-1),الاصناف!E:E,0),"💰 " & RIGHT(A7,LEN(A7)-FIND("|",A7)) & " $")) -> 💰 $
A8: قسطل المنيوم تلحيم 63 ملم اسود تركي| | B8: =IF(A8="","",HYPERLINK("#الاصناف!E"&MATCH(LEFT(A8,FIND("|",A8)-1),الاصناف!E:E,0),"✏️ " & LEFT(A8,FIND("|",A8)-1))) -> ✏️ قسطل المنيوم تلحيم 63 ملم اسود تركي | C8: =IF(A8="","",HYPERLINK("#الاصناف!G"&MATCH(LEFT(A8,FIND("|",A8)-1),الاصناف!E:E,0),"💰 " & RIGHT(A8,LEN(A8)-FIND("|",A8)) & " $")) -> 💰 $
A9: قسطل تلحيم 63 ملم ابيض تركي| | B9: =IF(A9="","",HYPERLINK("#الاصناف!E"&MATCH(LEFT(A9,FIND("|",A9)-1),الاصناف!E:E,0),"✏️ " & LEFT(A9,FIND("|",A9)-1))) -> ✏️ قسطل تلحيم 63 ملم ابيض تركي | C9: =IF(A9="","",HYPERLINK("#الاصناف!G"&MATCH(LEFT(A9,FIND("|",A9)-1),الاصناف!E:E,0),"💰 " & RIGHT(A9,LEN(A9)-FIND("|",A9)) & " $")) -> 💰 $
A10: قسطل تلحيم 63 ملم اخضر تركي|23 | B10: =IF(A10="","",HYPERLINK("#الاصناف!E"&MATCH(LEFT(A10,FIND("|",A10)-1),الاصناف!E:E,0),"✏️ " & LEFT(A10,FIND("|",A10)-1))) -> ✏️ قسطل تلحيم 63 ملم اخضر تركي | C10: =IF(A10="","",HYPERLINK("#الاصناف!G"&MATCH(LEFT(A10,FIND("|",A10)-1),الاصناف!E:E,0),"💰 " & RIGHT(A10,LEN(A10)-FIND("|",A10)) & " $")) -> 💰 23 $
A11: قسطل تلحيم 63 ملم اسود تركي| | B11: =IF(A11="","",HYPERLINK("#الاصناف!E"&MATCH(LEFT(A11,FIND("|",A11)-1),الاصناف!E:E,0),"✏️ " & LEFT(A11,FIND("|",A11)-1))) -> ✏️ قسطل تلحيم 63 ملم اسود تركي | C11: =IF(A11="","",HYPERLINK("#الاصناف!G"&MATCH(LEFT(A11,FIND("|",A11)-1),الاصناف!E:E,0),"💰 " & RIGHT(A11,LEN(A11)-FIND("|",A11)) & " $")) -> 💰 $
A12: قسطل تلحيم فيبر 63 ملم اخضر تركي| | B12: =IF(A12="","",HYPERLINK("#الاصناف!E"&MATCH(LEFT(A12,FIND("|",A12)-1),الاصناف!E:E,0),"✏️ " & LEFT(A12,FIND("|",A12)-1))) -> ✏️ قسطل تلحيم فيبر 63 ملم اخضر تركي | C12: =IF(A12="","",HYPERLINK("#الاصناف!G"&MATCH(LEFT(A12,FIND("|",A12)-1),الاصناف!E:E,0),"💰 " & RIGHT(A12,LEN(A12)-FIND("|",A12)) & " $")) -> 💰 $
A13: قسطل ضغط 63 ملم رمادي| | B13: =IF(A13="","",HYPERLINK("#الاصناف!E"&MATCH(LEFT(A13,FIND("|",A13)-1),الاصناف!E:E,0),"✏️ " & LEFT(A13,FIND("|",A13)-1))) -> ✏️ قسطل ضغط 63 ملم رمادي | C13: =IF(A13="","",HYPERLINK("#الاصناف!G"&MATCH(LEFT(A13,FIND("|",A13)-1),الاصناف!E:E,0),"💰 " & RIGHT(A13,LEN(A13)-FIND("|",A13)) & " $")) -> 💰 $
A14: قسطل تلحيم 63 ملم اخضر ايطالي ITALY RIETTI| | B14: =IF(A14="","",HYPERLINK("#الاصناف!E"&MATCH(LEFT(A14,FIND("|",A14)-1),الاصناف!E:E,0),"✏️ " & LEFT(A14,FIND("|",A14)-1))) -> ✏️ قسطل تلحيم 63 ملم اخضر ايطالي ITALY RIETTI | C14: =IF(A14="","",HYPERLINK("#الاصناف!G"&MATCH(LEFT(A14,FIND("|",A14)-1),الاصناف!E:E,0),"💰 " & RIGHT(A14,LEN(A14)-FIND("|",A14)) & " $")) -> 💰 $
B15: =IF(A15="","",HYPERLINK("#الاصناف!E"&MATCH(LEFT(A15,FIND("|",A15)-1),الاصناف!E:E,0),"✏️ " & LEFT(A15,FIND("|",A15)-1))) | C15: =IF(A15="","",HYPERLINK("#الاصناف!G"&MATCH(LEFT(A15,FIND("|",A15)-1),الاصناف!E:E,0),"💰 " & RIGHT(A15,LEN(A15)-FIND("|",A15)) & " $"))
B16: =IF(A16="","",HYPERLINK("#الاصناف!E"&MATCH(LEFT(A16,FIND("|",A16)-1),الاصناف!E:E,0),"✏️ " & LEFT(A16,FIND("|",A16)-1))) | C16: =IF(A16="","",HYPERLINK("#الاصناف!G"&MATCH(LEFT(A16,FIND("|",A16)-1),الاصناف!E:E,0),"💰 " & RIGHT(A16,LEN(A16)-FIND("|",A16)) & " $"))
B17: =IF(A17="","",HYPERLINK("#الاصناف!E"&MATCH(LEFT(A17,FIND("|",A17)-1),الاصناف!E:E,0),"✏️ " & LEFT(A17,FIND("|",A17)-1))) | C17: =IF(A17="","",HYPERLINK("#الاصناف!G"&MATCH(LEFT(A17,FIND("|",A17)-1),الاصناف!E:E,0),"💰 " & RIGHT(A17,LEN(A17)-FIND("|",A17)) & " $"))
B18: =IF(A18="","",HYPERLINK("#الاصناف!E"&MATCH(LEFT(A18,FIND("|",A18)-1),الاصناف!E:E,0),"✏️ " & LEFT(A18,FIND("|",A18)-1))) | C18: =IF(A18="","",HYPERLINK("#الاصناف!G"&MATCH(LEFT(A18,FIND("|",A18)-1),الاصناف!E:E,0),"💰 " & RIGHT(A18,LEN(A18)-FIND("|",A18)) & " $"))
B19: =IF(A19="","",HYPERLINK("#الاصناف!E"&MATCH(LEFT(A19,FIND("|",A19)-1),الاصناف!E:E,0),"✏️ " & LEFT(A19,FIND("|",A19)-1))) | C19: =IF(A19="","",HYPERLINK("#الاصناف!G"&MATCH(LEFT(A19,FIND("|",A19)-1),الاصناف!E:E,0),"💰 " & RIGHT(A19,LEN(A19)-FIND("|",A19)) & " $"))
B20: =IF(A20="","",HYPERLINK("#الاصناف!E"&MATCH(LEFT(A20,FIND("|",A20)-1),الاصناف!E:E,0),"✏️ " & LEFT(A20,FIND("|",A20)-1))) | C20: =IF(A20="","",HYPERLINK("#الاصناف!G"&MATCH(LEFT(A20,FIND("|",A20)-1),الاصناف!E:E,0),"💰 " & RIGHT(A20,LEN(A20)-FIND("|",A20)) & " $"))
B21: =IF(A21="","",HYPERLINK("#الاصناف!E"&MATCH(LEFT(A21,FIND("|",A21)-1),الاصناف!E:E,0),"✏️ " & LEFT(A21,FIND("|",A21)-1))) | C21: =IF(A21="","",HYPERLINK("#الاصناف!G"&MATCH(LEFT(A21,FIND("|",A21)-1),الاصناف!E:E,0),"💰 " & RIGHT(A21,LEN(A21)-FIND("|",A21)) & " $"))
B22: =IF(A22="","",HYPERLINK("#الاصناف!E"&MATCH(LEFT(A22,FIND("|",A22)-1),الاصناف!E:E,0),"✏️ " & LEFT(A22,FIND("|",A22)-1))) | C22: =IF(A22="","",HYPERLINK("#الاصناف!G"&MATCH(LEFT(A22,FIND("|",A22)-1),الاصناف!E:E,0),"💰 " & RIGHT(A22,LEN(A22)-FIND("|",A22)) & " $"))
B23: =IF(A23="","",HYPERLINK("#الاصناف!E"&MATCH(LEFT(A23,FIND("|",A23)-1),الاصناف!E:E,0),"✏️ " & LEFT(A23,FIND("|",A23)-1))) | C23: =IF(A23="","",HYPERLINK("#الاصناف!G"&MATCH(LEFT(A23,FIND("|",A23)-1),الاصناف!E:E,0),"💰 " & RIGHT(A23,LEN(A23)-FIND("|",A23)) & " $"))
B24: =IF(A24="","",HYPERLINK("#الاصناف!E"&MATCH(LEFT(A24,FIND("|",A24)-1),الاصناف!E:E,0),"✏️ " & LEFT(A24,FIND("|",A24)-1))) | C24: =IF(A24="","",HYPERLINK("#الاصناف!G"&MATCH(LEFT(A24,FIND("|",A24)-1),الاصناف!E:E,0),"💰 " & RIGHT(A24,LEN(A24)-FIND("|",A24)) & " $"))
B25: =IF(A25="","",HYPERLINK("#الاصناف!E"&MATCH(LEFT(A25,FIND("|",A25)-1),الاصناف!E:E,0),"✏️ " & LEFT(A25,FIND("|",A25)-1))) | C25: =IF(A25="","",HYPERLINK("#الاصناف!G"&MATCH(LEFT(A25,FIND("|",A25)-1),الاصناف!E:E,0),"💰 " & RIGHT(A25,LEN(A25)-FIND("|",A25)) & " $"))
B26: =IF(A26="","",HYPERLINK("#الاصناف!E"&MATCH(LEFT(A26,FIND("|",A26)-1),الاصناف!E:E,0),"✏️ " & LEFT(A26,FIND("|",A26)-1))) | C26: =IF(A26="","",HYPERLINK("#الاصناف!G"&MATCH(LEFT(A26,FIND("|",A26)-1),الاصناف!E:E,0),"💰 " & RIGHT(A26,LEN(A26)-FIND("|",A26)) & " $"))
... B500: =IF(A500="","",HYPERLINK("#الاصناف!E"&MATCH(LEFT(A500,FIND("|",A500)-1),الاصناف!E:E,0),"✏️ " & LEFT(A500,FIND("|",A500)-1))) | C500: =IF(A500="","",HYPERLINK("#الاصناف!G"&MATCH(LEFT(A500,FIND("|",A500)-1),الاصناف!E:E,0),"💰 " & RIGHT(A500,LEN(A500)-FIND("|",A500)) & " $"))

Sheet المسعّر
A1: Item_name | B1: Sale1
A2: {=_xlfn.LET( _xlpm.data, _xlfn._xlws.FILTER(الاصناف!E2:G9992, الاصناف!G2:G9992>0), IF(COUNTA(_xlpm.data)=0, "لا نتائج", _xlfn.CHOOSECOLS(_xlpm.data, 1, 3)) )} -> LEO 2ACm150 2HP 220V موتير ليو توربين | B2: 175
A3: LEO 4 ACM/60 طلمبة ماء صامته | B3: 100
A4: LEO 4 ACM/75 طلمبة ماء صامتة | B4: 125
A5: LEO PQ50E طلمبة ماء اتوماتيك مع غطاء | B5: 80
A6: LEO PRESS CONTROL | B6: 25
A7: LEO موتير 0.5 حصان صامت ليو 3ACM45 | B7: 85
A8: LEO موتير 0.5 حصان ليو ACM37 TURBINE | B8: 75
A9: LEO موتير 0.5 حصان ليو APM37 | B9: 35
A10: LEO موتير 0.75 حصان ليو APM 60 | B10: 55
A11: LEO موتير 1 حصان صامت ليو | B11: 120
A12: LEO موتير 1 حصان ليو APM 90 طلمبة ماء | B12: 95
A13: LEO موتير 1.5 حصان ليو APM 110 طلمبة ماء عادي | B13: 145
A14: LEO موتير اتوماتيك ليو XKSM13O طرمبة مع برس كنترول | B14: 75
... A721: رزستانس طاقه شمسيه 1 انش | B721: 25
